<?xml version="1.0"?>
<robot name="Cuong_MobileRobot" xmlns:xacro="http://www.ros.org/wiki/xacro" >



  <!-- BASE LINK -->

  <link name="base_footprint">
  </link>
  <joint name="base_footprint_joint" type="fixed">
    <origin xyz="0 0 0" />
    <parent link="base_footprint" />
    <child link="base_link" />
  </joint>

  <!-- Chassis LINK -->

  <link name="base_link">
   <inertial>
      <origin
        xyz="-0.00887608577321029 7.15767558960218E-06 0.0787840514491733"
        rpy="0 0 0" />
      <mass
        value="1.28133453331002" />
      <inertia
        ixx="0.0468244369690289"
        ixy="-3.4613336007172E-06"
        ixz="4.34454889010329E-05"
        iyy="0.0240341123957385"
        iyz="-1.32432557062817E-06"
        izz="0.0664423696630811" />
    </inertial>
    <visual>
      <origin
        xyz="0 0 0"
        rpy="0 0 0" />
      <geometry>
        <mesh
          filename="file://$(find myrobot)/meshes//base_link.STL" />
      </geometry>
      <material name="gray"/>
    </visual>
    <collision>
      <origin
        xyz="0 0 0"
        rpy="0 0 0" />
      <geometry>
        <mesh
          filename="file://$(find myrobot)/meshes//base_link.STL" />
      </geometry>
    </collision>
  </link>

  <!-- RightDrive_link -->

  <link name="RD_link">
    <inertial>
      <origin
        xyz="7.87594729263556E-06 3.21954041912487E-07 -0.00125132754173546"
        rpy="0 0 0" />
      <mass
        value="0.268087345954588" />
      <inertia
        ixx="0.0001926951796097"
        ixy="8.03209264984212E-10"
        ixz="6.3660498983915E-08"
        iyy="0.000192675558238293"
        iyz="2.60289310470105E-09"
        izz="0.00032009896690558" />
    </inertial>
    <visual>
      <origin
        xyz="0 0 0"
        rpy="0 0 0" />
      <geometry>
        <mesh
          filename="file://$(find myrobot)/meshes//RD_link.STL" />
      </geometry>
      <material name="white"/>
    </visual>
    <collision>
      <origin
        xyz="0 0 0"
        rpy="0 0 0" />
      <geometry>
        <mesh
          filename="file://$(find myrobot)/meshes//RD_link.STL" />
      </geometry>
    </collision>
  </link>
  <joint name="RD_joint"
    type="continuous">
    <origin xyz="0 -0.2014 0.03" rpy="1.5707963267949 0 0" />
    <parent link="base_link" />
    <child link="RD_link" />
    <axis xyz="0 0 1" />
  </joint>

  <!-- LeftDrive_link -->

  <link name="LD_link">
    <inertial>
      <origin
        xyz="-3.79337303156049E-06 -6.90974103747036E-06 0.00125132754173543"
        rpy="0 0 0" />
      <mass
        value="0.268087345954588" />
      <inertia
        ixx="0.000192680084553262"
        ixy="8.30482540674649E-09"
        ixz="3.06619680704156E-08"
        iyy="0.000192690653294731"
        iyz="5.5850495946252E-08"
        izz="0.00032009896690558" />
    </inertial>
    <visual>
      <origin
        xyz="0 0 0"
        rpy="0 0 0" />
      <geometry>
        <mesh
          filename="file://$(find myrobot)/meshes//LD_link.STL" />
      </geometry>
      <material name="white"/>
    </visual>
    <collision>
      <origin
        xyz="0 0 0"
        rpy="0 0 0" />
      <geometry>
        <mesh
          filename="file://$(find myrobot)/meshes//LD_link.STL" />
      </geometry>
    </collision>
  </link>
  <joint name="LD_joint"
    type="continuous">
    <origin
      xyz="0 0.2014 0.03"
      rpy="1.5707963267949 0 0" />
    <parent
      link="base_link" />
    <child
      link="LD_link" />
    <axis
      xyz="0 0 -1" />
  </joint>

  <!-- BackRightCaster_link -->

  <link name="BRC_link">
    <inertial>
      <origin
        xyz="0.00480643793588634 0.00813240295364562 5.61462762532772E-08"
        rpy="0 0 0" />
      <mass
        value="0.028455048288764" />
      <inertia
        ixx="3.94774719095158E-06"
        ixy="-2.92353662392493E-07"
        ixz="-7.18479870958837E-11"
        iyy="4.24152605662568E-06"
        iyz="-8.83598650868593E-12"
        izz="5.71387977555985E-06" />
    </inertial>
    <visual>
      <origin
        xyz="0 0 0"
        rpy="0 0 0" />
      <geometry>
        <mesh
          filename="file://$(find myrobot)/meshes//BRC_link.STL" />
      </geometry>
      <material name="white"/>
    </visual>
    <collision>
      <origin
        xyz="0 0 0"
        rpy="0 0 0" />
      <geometry>
        <mesh
          filename="file://$(find myrobot)/meshes//BRC_link.STL" />
      </geometry>
    </collision>
  </link>
  <joint name="BRC_joint"
    type="fixed">
    <origin
      xyz="-0.166647236505441 -0.12 0"
      rpy="1.5707963267949 0 0" />
    <parent
      link="base_link" />
    <child
      link="BRC_link" />
    <axis
      xyz="0 0 0" />
  </joint>
  
  <!-- BackLeftCaster_link -->

  <link name="BLC_link">
    <inertial>
      <origin
        xyz="0.00480643793588639 0.00813240295364563 5.61462762393994E-08"
        rpy="0 0 0" />
      <mass
        value="0.0284550482887641" />
      <inertia
        ixx="3.9477471909516E-06"
        ixy="-2.92353662392497E-07"
        ixz="-7.18479870979925E-11"
        iyy="4.24152605662568E-06"
        iyz="-8.83598650523835E-12"
        izz="5.71387977555987E-06" />
    </inertial>
    <visual>
      <origin
        xyz="0 0 0"
        rpy="0 0 0" />
      <geometry>
        <mesh
          filename="file://$(find myrobot)/meshes//BLC_link.STL" />
      </geometry>
      <material name="white"/>
    </visual>
    <collision>
      <origin
        xyz="0 0 0"
        rpy="0 0 0" />
      <geometry>
        <mesh
          filename="file://$(find myrobot)/meshes//BLC_link.STL" />
      </geometry>
    </collision>
  </link>
  <joint name="BLC_joint"
    type="fixed">
    <origin
      xyz="-0.166647236505441 0.12 0"
      rpy="1.5707963267949 0 0" />
    <parent
      link="base_link" />
    <child
      link="BLC_link" />
    <axis
      xyz="0 0 0" />
  </joint>
  
  <!-- FrontRightCaster_link -->
  <link name="FRC_link">
    <inertial>
      <origin
        xyz="0.00480643793588634 0.00813240295364561 5.61462762255216E-08"
        rpy="0 0 0" />
      <mass
        value="0.028455048288764" />
      <inertia
        ixx="3.94774719095158E-06"
        ixy="-2.92353662392493E-07"
        ixz="-7.1847987094674E-11"
        iyy="4.24152605662568E-06"
        iyz="-8.83598650915944E-12"
        izz="5.71387977555985E-06" />
    </inertial>
    <visual>
      <origin
        xyz="0 0 0"
        rpy="0 0 0" />
      <geometry>
        <mesh
          filename="file://$(find myrobot)/meshes//FRC_link.STL" />
      </geometry>
      <material name="white"/>
    </visual>
    <collision>
      <origin
        xyz="0 0 0"
        rpy="0 0 0" />
      <geometry>
        <mesh
          filename="file://$(find myrobot)/meshes//FRC_link.STL" />
      </geometry>
    </collision>
  </link>
  <joint name="FRC_joint"
    type="fixed">
    <origin
      xyz="0.123352763494559 -0.12 0"
      rpy="1.5707963267949 0 0" />
    <parent
      link="base_link" />
    <child
      link="FRC_link" />
    <axis
      xyz="0 0 0" />
  </joint>
  
  <!-- FrontLeftCaster_link -->
  <link name="FLC_link">
    <inertial>
      <origin
        xyz="0.00480629250534995 0.0081324029536456 -3.73896736640678E-05"
        rpy="0 0 0" />
      <mass
        value="0.028455048288764" />
      <inertia
        ixx="3.94785326864327E-06"
        ixy="-2.9234485875001E-07"
        ixz="1.36872633286527E-08"
        iyy="4.24152605662567E-06"
        iyz="2.26882234125641E-09"
        izz="5.71377369786818E-06" />
    </inertial>
    <visual>
      <origin
        xyz="0 0 0"
        rpy="0 0 0" />
      <geometry>
        <mesh
          filename="file://$(find myrobot)/meshes//FLC_link.STL" />
      </geometry>
      <material name="white"/>
    </visual>
    <collision>
      <origin
        xyz="0 0 0"
        rpy="0 0 0" />
      <geometry>
        <mesh
          filename="file://$(find myrobot)/meshes//FLC_link.STL" />
      </geometry>
    </collision>
  </link>
  <joint name="FLC_joint"
    type="fixed">
    <origin
      xyz="0.123353420454712 0.119831351513467 0"
      rpy="1.5707963267949 0 0" />
    <parent
      link="base_link" />
    <child
      link="FLC_link" />
    <axis
      xyz="0 1 0" />
  </joint>
  
  <!-- Lidar_link -->
  <link name="Lidar_link">
    <inertial>
      <origin
        xyz="0.00387034276639205 -1.45281231590543E-05 -0.00554960506491434"
        rpy="0 0 0" />
      <mass
        value="0.165382847444673" />
      <inertia
        ixx="7.88658059973056E-05"
        ixy="4.83601286757989E-08"
        ixz="2.18507688491495E-06"
        iyy="7.51891529441991E-05"
        iyz="2.8831474631393E-08"
        izz="0.00010994637923249" />
    </inertial>
    <visual>
      <origin
        xyz="0 0 0"
        rpy="0 0 0" />
      <geometry>
        <mesh
          filename="file://$(find myrobot)/meshes//Lidar_link.STL" />
      </geometry>
      <material name="white"/>
    </visual>
    <collision>
      <origin
        xyz="0 0 0"
        rpy="0 0 0" />
      <geometry>
        <mesh
          filename="file://$(find myrobot)/meshes//Lidar_link.STL" />
      </geometry>
    </collision>
  </link>
  <joint name="Lidar_joint"
    type="fixed">
    <origin
      xyz="-0.00443560268497129 0 0.249848176885676"
      rpy="0 0 0" />
    <parent
      link="base_link" />
    <child
      link="Lidar_link" />
    <axis
      xyz="0 0 0" />
  </joint>


  <material name="white">
    <color rgba="1 1 1 1" />
  </material>

  <material name="gray">
    <color rgba="0.5 0.5 0.5 1"/>
  </material>

  <material name="blue">
    <color rgba="0.2 0.2 1 1"/>
  </material>

  <material name="black">
    <color rgba="0 0 0 1"/>
  </material>

</robot>
